2023-12-15 11:32:39,552 [ERROR] - 发生错误: 这是一个示例错误
Traceback (most recent call last):
  File "E:\work\mr_dea_data_c2\new_mr_umer_c1\log_demo.py", line 16, in example_function
    raise ValueError("这是一个示例错误")
ValueError: 这是一个示例错误
